/home/seheyura/virtualenv/django_sclive/3.11/lib/python3.11/site-packages/sentry_sdk/integrations/django/middleware.py:136: UserWarning: No directory at: /home/seheyura/django_sclive/staticfiles/
  self._inner = middleware(get_response, *args, **kwargs)
/home/seheyura/virtualenv/django_sclive/3.11/lib/python3.11/site-packages/sentry_sdk/integrations/django/middleware.py:136: UserWarning: No directory at: /home/seheyura/django_sclive/staticfiles/
  self._inner = middleware(get_response, *args, **kwargs)
--- Logging error ---
Traceback (most recent call last):
  File "/home/seheyura/virtualenv/django_sclive/3.11/lib/python3.11/site-packages/django/core/handlers/exception.py", line 55, in inner
    response = get_response(request)
               ^^^^^^^^^^^^^^^^^^^^^
  File "/home/seheyura/virtualenv/django_sclive/3.11/lib/python3.11/site-packages/django/core/handlers/base.py", line 197, in _get_response
    response = wrapped_callback(request, *callback_args, **callback_kwargs)
               ^^^^^^^^^^^^^^^^^^^^^^^^^^^^^^^^^^^^^^^^^^^^^^^^^^^^^^^^^^^^
  File "/home/seheyura/virtualenv/django_sclive/3.11/lib/python3.11/site-packages/django/contrib/auth/decorators.py", line 23, in _wrapper_view
    return view_func(request, *args, **kwargs)
           ^^^^^^^^^^^^^^^^^^^^^^^^^^^^^^^^^^^
  File "/home/seheyura/django_sclive/core/views/leave_invoice_views.py", line 265, in leave_invoice_detail
    print(f"\u0639\u062f\u062f \u0627\u0644\u0645\u062f\u0641\u0648\u0639\u0627\u062a \u0627\u0644\u0645\u0631\u062a\u0628\u0637\u0629 \u0628\u0627\u0644\u0641\u0627\u062a\u0648\u0631\u0629: {payment_details.count()}")
UnicodeEncodeError: 'ascii' codec can't encode characters in position 0-2: ordinal not in range(128)

During handling of the above exception, another exception occurred:

Traceback (most recent call last):
  File "/opt/alt/python311/lib64/python3.11/logging/__init__.py", line 1113, in emit
    stream.write(msg + self.terminator)
UnicodeEncodeError: 'ascii' codec can't encode characters in position 980-982: ordinal not in range(128)
Call stack:
  File "/home/seheyura/virtualenv/django_sclive/3.11/lib/python3.11/site-packages/django/core/handlers/wsgi.py", line 124, in __call__
    response = self.get_response(request)
  File "/home/seheyura/virtualenv/django_sclive/3.11/lib/python3.11/site-packages/django/core/handlers/base.py", line 140, in get_response
    response = self._middleware_chain(request)
  File "/home/seheyura/virtualenv/django_sclive/3.11/lib/python3.11/site-packages/django/core/handlers/exception.py", line 55, in inner
    response = get_response(request)
  File "/home/seheyura/virtualenv/django_sclive/3.11/lib/python3.11/site-packages/django/utils/deprecation.py", line 134, in __call__
    response = response or self.get_response(request)
  File "/home/seheyura/virtualenv/django_sclive/3.11/lib/python3.11/site-packages/django/core/handlers/exception.py", line 55, in inner
    response = get_response(request)
  File "/home/seheyura/virtualenv/django_sclive/3.11/lib/python3.11/site-packages/django/utils/deprecation.py", line 134, in __call__
    response = response or self.get_response(request)
  File "/home/seheyura/virtualenv/django_sclive/3.11/lib/python3.11/site-packages/django/core/handlers/exception.py", line 55, in inner
    response = get_response(request)
  File "/home/seheyura/virtualenv/django_sclive/3.11/lib/python3.11/site-packages/django/utils/deprecation.py", line 134, in __call__
    response = response or self.get_response(request)
  File "/home/seheyura/virtualenv/django_sclive/3.11/lib/python3.11/site-packages/django/core/handlers/exception.py", line 55, in inner
    response = get_response(request)
  File "/home/seheyura/virtualenv/django_sclive/3.11/lib/python3.11/site-packages/django/utils/deprecation.py", line 134, in __call__
    response = response or self.get_response(request)
  File "/home/seheyura/virtualenv/django_sclive/3.11/lib/python3.11/site-packages/django/core/handlers/exception.py", line 55, in inner
    response = get_response(request)
  File "/home/seheyura/virtualenv/django_sclive/3.11/lib/python3.11/site-packages/django/utils/deprecation.py", line 134, in __call__
    response = response or self.get_response(request)
  File "/home/seheyura/virtualenv/django_sclive/3.11/lib/python3.11/site-packages/django/core/handlers/exception.py", line 55, in inner
    response = get_response(request)
  File "/home/seheyura/virtualenv/django_sclive/3.11/lib/python3.11/site-packages/django/utils/deprecation.py", line 134, in __call__
    response = response or self.get_response(request)
  File "/home/seheyura/virtualenv/django_sclive/3.11/lib/python3.11/site-packages/django/core/handlers/exception.py", line 55, in inner
    response = get_response(request)
  File "/home/seheyura/virtualenv/django_sclive/3.11/lib/python3.11/site-packages/django/utils/deprecation.py", line 134, in __call__
    response = response or self.get_response(request)
  File "/home/seheyura/virtualenv/django_sclive/3.11/lib/python3.11/site-packages/django/core/handlers/exception.py", line 55, in inner
    response = get_response(request)
  File "/home/seheyura/virtualenv/django_sclive/3.11/lib/python3.11/site-packages/django/utils/deprecation.py", line 134, in __call__
    response = response or self.get_response(request)
  File "/home/seheyura/virtualenv/django_sclive/3.11/lib/python3.11/site-packages/django/core/handlers/exception.py", line 57, in inner
    response = response_for_exception(request, exc)
  File "/home/seheyura/virtualenv/django_sclive/3.11/lib/python3.11/site-packages/django/core/handlers/exception.py", line 143, in response_for_exception
    log_response(
  File "/home/seheyura/virtualenv/django_sclive/3.11/lib/python3.11/site-packages/django/utils/log.py", line 241, in log_response
    getattr(logger, level)(
Message: '%s: %s'
Arguments: ('Internal Server Error', '/leave-invoices/6/')
--- Logging error ---
Traceback (most recent call last):
  File "/home/seheyura/virtualenv/django_sclive/3.11/lib/python3.11/site-packages/django/core/handlers/exception.py", line 55, in inner
    response = get_response(request)
               ^^^^^^^^^^^^^^^^^^^^^
  File "/home/seheyura/virtualenv/django_sclive/3.11/lib/python3.11/site-packages/django/core/handlers/base.py", line 197, in _get_response
    response = wrapped_callback(request, *callback_args, **callback_kwargs)
               ^^^^^^^^^^^^^^^^^^^^^^^^^^^^^^^^^^^^^^^^^^^^^^^^^^^^^^^^^^^^
  File "/home/seheyura/virtualenv/django_sclive/3.11/lib/python3.11/site-packages/django/contrib/auth/decorators.py", line 23, in _wrapper_view
    return view_func(request, *args, **kwargs)
           ^^^^^^^^^^^^^^^^^^^^^^^^^^^^^^^^^^^
  File "/home/seheyura/django_sclive/core/views/leave_invoice_views.py", line 265, in leave_invoice_detail
    print(f"\u0639\u062f\u062f \u0627\u0644\u0645\u062f\u0641\u0648\u0639\u0627\u062a \u0627\u0644\u0645\u0631\u062a\u0628\u0637\u0629 \u0628\u0627\u0644\u0641\u0627\u062a\u0648\u0631\u0629: {payment_details.count()}")
UnicodeEncodeError: 'ascii' codec can't encode characters in position 0-2: ordinal not in range(128)

During handling of the above exception, another exception occurred:

Traceback (most recent call last):
  File "/opt/alt/python311/lib64/python3.11/logging/__init__.py", line 1113, in emit
    stream.write(msg + self.terminator)
UnicodeEncodeError: 'ascii' codec can't encode characters in position 980-982: ordinal not in range(128)
Call stack:
  File "/home/seheyura/virtualenv/django_sclive/3.11/lib/python3.11/site-packages/django/core/handlers/wsgi.py", line 124, in __call__
    response = self.get_response(request)
  File "/home/seheyura/virtualenv/django_sclive/3.11/lib/python3.11/site-packages/django/core/handlers/base.py", line 140, in get_response
    response = self._middleware_chain(request)
  File "/home/seheyura/virtualenv/django_sclive/3.11/lib/python3.11/site-packages/django/core/handlers/exception.py", line 55, in inner
    response = get_response(request)
  File "/home/seheyura/virtualenv/django_sclive/3.11/lib/python3.11/site-packages/django/utils/deprecation.py", line 134, in __call__
    response = response or self.get_response(request)
  File "/home/seheyura/virtualenv/django_sclive/3.11/lib/python3.11/site-packages/django/core/handlers/exception.py", line 55, in inner
    response = get_response(request)
  File "/home/seheyura/virtualenv/django_sclive/3.11/lib/python3.11/site-packages/django/utils/deprecation.py", line 134, in __call__
    response = response or self.get_response(request)
  File "/home/seheyura/virtualenv/django_sclive/3.11/lib/python3.11/site-packages/django/core/handlers/exception.py", line 55, in inner
    response = get_response(request)
  File "/home/seheyura/virtualenv/django_sclive/3.11/lib/python3.11/site-packages/django/utils/deprecation.py", line 134, in __call__
    response = response or self.get_response(request)
  File "/home/seheyura/virtualenv/django_sclive/3.11/lib/python3.11/site-packages/django/core/handlers/exception.py", line 55, in inner
    response = get_response(request)
  File "/home/seheyura/virtualenv/django_sclive/3.11/lib/python3.11/site-packages/django/utils/deprecation.py", line 134, in __call__
    response = response or self.get_response(request)
  File "/home/seheyura/virtualenv/django_sclive/3.11/lib/python3.11/site-packages/django/core/handlers/exception.py", line 55, in inner
    response = get_response(request)
  File "/home/seheyura/virtualenv/django_sclive/3.11/lib/python3.11/site-packages/django/utils/deprecation.py", line 134, in __call__
    response = response or self.get_response(request)
  File "/home/seheyura/virtualenv/django_sclive/3.11/lib/python3.11/site-packages/django/core/handlers/exception.py", line 55, in inner
    response = get_response(request)
  File "/home/seheyura/virtualenv/django_sclive/3.11/lib/python3.11/site-packages/django/utils/deprecation.py", line 134, in __call__
    response = response or self.get_response(request)
  File "/home/seheyura/virtualenv/django_sclive/3.11/lib/python3.11/site-packages/django/core/handlers/exception.py", line 55, in inner
    response = get_response(request)
  File "/home/seheyura/virtualenv/django_sclive/3.11/lib/python3.11/site-packages/django/utils/deprecation.py", line 134, in __call__
    response = response or self.get_response(request)
  File "/home/seheyura/virtualenv/django_sclive/3.11/lib/python3.11/site-packages/django/core/handlers/exception.py", line 55, in inner
    response = get_response(request)
  File "/home/seheyura/virtualenv/django_sclive/3.11/lib/python3.11/site-packages/django/utils/deprecation.py", line 134, in __call__
    response = response or self.get_response(request)
  File "/home/seheyura/virtualenv/django_sclive/3.11/lib/python3.11/site-packages/django/core/handlers/exception.py", line 57, in inner
    response = response_for_exception(request, exc)
  File "/home/seheyura/virtualenv/django_sclive/3.11/lib/python3.11/site-packages/django/core/handlers/exception.py", line 143, in response_for_exception
    log_response(
  File "/home/seheyura/virtualenv/django_sclive/3.11/lib/python3.11/site-packages/django/utils/log.py", line 241, in log_response
    getattr(logger, level)(
Message: '%s: %s'
Arguments: ('Internal Server Error', '/leave-invoices/6/')
WARNING Forbidden (CSRF token from POST incorrect.): /inquiries/slenquiry/
WARNING Forbidden (Referer checking failed - no Referer.): /
